<mujoco model="panda">
  <!-- <include file="DPHand.xml"/> -->
  <compiler angle="radian"/>

  <option impratio="10" cone="elliptic"/>

  <default>
    <default class="panda">
      <joint range="-2.8973 2.8973" armature="0.1" damping="1"/>
      <site size="0.001 0.005 0.005" group="4" rgba="0.5 0.5 0.5 0.3"/>
      <default class="panda/visual">
        <geom type="mesh" contype="0" conaffinity="0" group="2"/>
      </default>
      <default class="panda/collision">
        <geom type="mesh" group="3"/>
      </default>
    </default>
    <default class="plastic">
      <geom type="mesh" solref="0.005" solimp="0.5 0.99 0.0001" material="black"/>
    </default>
    <default class="jointconfig">
      <joint armature="0.0002" damping="0.01" frictionloss="0.01"/>
    </default>
    <default class="DIPCtrl">
      <joint range="0 1.22173"/>
      <general ctrlrange="0 1.22173" forcerange="-20 20" biastype="affine" gainprm="0.2" biasprm="0 -0.2 0.9"/>
    </default>
    <default class="PIPCtrl">
      <joint range="0 1.91986"/>
      <general ctrlrange="0 1.91986" forcerange="-20.063 20.063" biastype="affine" gainprm="0.2" biasprm="0 -0.2 0.9"/>
    </default>
    <default class="MCPCtrl">
      <joint range="-0.523599 1.5708"/>
      <general ctrlrange="-0.523599 1.5708" forcerange="-40.83 40.83" biastype="affine" gainprm="0.2" biasprm="0 -0.2 0.9"/>
    </default>
    <default class="MCP2Ctrl">
      <joint range="-0.610865 0.610865"/>
      <general ctrlrange="-0.610865 0.610865" forcerange="-20.45 20.45" biastype="affine" gainprm="0.2" biasprm="0 -0.2 0.9"/>
    </default>
  </default>

  <asset>
    <material name="white"/>
    <material name="off_white" rgba="0.901961 0.921569 0.929412 1"/>
    <material name="dark_grey" rgba="0.25 0.25 0.25 1"/>
    <material name="green" rgba="0 1 0 1"/>
    <material name="light_blue" rgba="0.039216 0.541176 0.780392 1"/>
    <material name="metal" rgba="0.58 0.58 0.58 1"/>
    <material name="silicone" rgba="0.1882 0.1882 0.1882 1"/>
    <material name="transparent_black" shininess="0.25" rgba="0.2 0.2 0.2 0.5"/>
    <material name="black" shininess="0.25" rgba="0.2 0.2 0.2 1"/>
    <material name="gray" specular="0" rgba="0.80848 0.80848 0.80848 1"/>
    <mesh name="link0_c" file="franka_emika_panda/assets/link0.stl"/>
    <mesh name="link1_c" file="franka_emika_panda/assets/link1.stl"/>
    <mesh name="link2_c" file="franka_emika_panda/assets/link2.stl"/>
    <mesh name="link3_c" file="franka_emika_panda/assets/link3.stl"/>
    <mesh name="link4_c" file="franka_emika_panda/assets/link4.stl"/>
    <mesh name="link5_c0" file="franka_emika_panda/assets/link5_collision_0.obj"/>
    <mesh name="link5_c1" file="franka_emika_panda/assets/link5_collision_1.obj"/>
    <mesh name="link5_c2" file="franka_emika_panda/assets/link5_collision_2.obj"/>
    <mesh name="link6_c" file="franka_emika_panda/assets/link6.stl"/>
    <mesh name="link7_c" file="franka_emika_panda/assets/link7.stl"/>
    <mesh name="link0_0" file="franka_emika_panda/assets/link0_0.obj"/>
    <mesh name="link0_1" file="franka_emika_panda/assets/link0_1.obj"/>
    <mesh name="link0_2" file="franka_emika_panda/assets/link0_2.obj"/>
    <mesh name="link0_3" file="franka_emika_panda/assets/link0_3.obj"/>
    <mesh name="link0_4" file="franka_emika_panda/assets/link0_4.obj"/>
    <mesh name="link0_5" file="franka_emika_panda/assets/link0_5.obj"/>
    <mesh name="link0_7" file="franka_emika_panda/assets/link0_7.obj"/>
    <mesh name="link0_8" file="franka_emika_panda/assets/link0_8.obj"/>
    <mesh name="link0_9" file="franka_emika_panda/assets/link0_9.obj"/>
    <mesh name="link0_10" file="franka_emika_panda/assets/link0_10.obj"/>
    <mesh name="link0_11" file="franka_emika_panda/assets/link0_11.obj"/>
    <mesh name="link1" file="franka_emika_panda/assets/link1.obj"/>
    <mesh name="link2" file="franka_emika_panda/assets/link2.obj"/>
    <mesh name="link3_0" file="franka_emika_panda/assets/link3_0.obj"/>
    <mesh name="link3_1" file="franka_emika_panda/assets/link3_1.obj"/>
    <mesh name="link3_2" file="franka_emika_panda/assets/link3_2.obj"/>
    <mesh name="link3_3" file="franka_emika_panda/assets/link3_3.obj"/>
    <mesh name="link4_0" file="franka_emika_panda/assets/link4_0.obj"/>
    <mesh name="link4_1" file="franka_emika_panda/assets/link4_1.obj"/>
    <mesh name="link4_2" file="franka_emika_panda/assets/link4_2.obj"/>
    <mesh name="link4_3" file="franka_emika_panda/assets/link4_3.obj"/>
    <mesh name="link5_0" file="franka_emika_panda/assets/link5_0.obj"/>
    <mesh name="link5_1" file="franka_emika_panda/assets/link5_1.obj"/>
    <mesh name="link5_2" file="franka_emika_panda/assets/link5_2.obj"/>
    <mesh name="link6_0" file="franka_emika_panda/assets/link6_0.obj"/>
    <mesh name="link6_1" file="franka_emika_panda/assets/link6_1.obj"/>
    <mesh name="link6_2" file="franka_emika_panda/assets/link6_2.obj"/>
    <mesh name="link6_3" file="franka_emika_panda/assets/link6_3.obj"/>
    <mesh name="link6_4" file="franka_emika_panda/assets/link6_4.obj"/>
    <mesh name="link6_5" file="franka_emika_panda/assets/link6_5.obj"/>
    <mesh name="link6_6" file="franka_emika_panda/assets/link6_6.obj"/>
    <mesh name="link6_7" file="franka_emika_panda/assets/link6_7.obj"/>
    <mesh name="link6_8" file="franka_emika_panda/assets/link6_8.obj"/>
    <mesh name="link6_9" file="franka_emika_panda/assets/link6_9.obj"/>
    <mesh name="link6_10" file="franka_emika_panda/assets/link6_10.obj"/>
    <mesh name="link6_11" file="franka_emika_panda/assets/link6_11.obj"/>
    <mesh name="link6_12" file="franka_emika_panda/assets/link6_12.obj"/>
    <mesh name="link6_13" file="franka_emika_panda/assets/link6_13.obj"/>
    <mesh name="link6_14" file="franka_emika_panda/assets/link6_14.obj"/>
    <mesh name="link6_15" file="franka_emika_panda/assets/link6_15.obj"/>
    <mesh name="link6_16" file="franka_emika_panda/assets/link6_16.obj"/>
    <mesh name="link7_0" file="franka_emika_panda/assets/link7_0.obj"/>
    <mesh name="link7_1" file="franka_emika_panda/assets/link7_1.obj"/>
    <mesh name="link7_2" file="franka_emika_panda/assets/link7_2.obj"/>
    <mesh name="link7_3" file="franka_emika_panda/assets/link7_3.obj"/>
    <mesh name="link7_4" file="franka_emika_panda/assets/link7_4.obj"/>
    <mesh name="link7_5" file="franka_emika_panda/assets/link7_5.obj"/>
    <mesh name="link7_6" file="franka_emika_panda/assets/link7_6.obj"/>
    <mesh name="link7_7" file="franka_emika_panda/assets/link7_7.obj"/>
    <mesh name="Wrist" file="dphand/meshes_obj/Wrist.obj" scale="0.001 0.001 0.001"/>
    <mesh name="Palm" file="dphand/meshes_obj/Palm.obj" scale="0.001 0.001 0.001"/>
    <mesh name="Thumb-MCP" file="dphand/meshes_obj/MCP.obj" scale="0.001 0.001 0.001"/>
    <mesh name="Thumb-PP" file="dphand/meshes_obj/PP.obj" scale="0.001 0.001 0.001"/>
    <mesh name="Thumb-PM" file="dphand/meshes_obj/PM.obj" scale="0.001 0.001 0.001"/>
    <mesh name="Thumb-PD" file="dphand/meshes_obj/PD.obj" scale="0.001 0.001 0.001"/>
    <mesh name="Index-PP" file="dphand/meshes_obj/PP.obj" scale="0.001 0.001 0.001"/>
    <mesh name="Index-PM" file="dphand/meshes_obj/PM.obj" scale="0.001 0.001 0.001"/>
    <mesh name="Index-PD" file="dphand/meshes_obj/PD.obj" scale="0.001 0.001 0.001"/>
    <mesh name="Middle-PD" file="dphand/meshes_obj/PD.obj" scale="0.001 0.001 0.001"/>
    <mesh name="Middle-PM" file="dphand/meshes_obj/PM.obj" scale="0.001 0.001 0.001"/>
    <mesh name="Middle-PP" file="dphand/meshes_obj/PP.obj" scale="0.001 0.001 0.001"/>
    <mesh name="Middle-MCP" file="dphand/meshes_obj/MCP.obj" scale="0.001 0.001 0.001"/>
    <mesh name="Ring-MCP" file="dphand/meshes_obj/MCP.obj" scale="0.001 0.001 0.001"/>
    <mesh name="Ring-PP" file="dphand/meshes_obj/PP.obj" scale="0.001 0.001 0.001"/>
    <mesh name="Ring-PM" file="dphand/meshes_obj/PM.obj" scale="0.001 0.001 0.001"/>
    <mesh name="Ring-PD" file="dphand/meshes_obj/PD.obj" scale="0.001 0.001 0.001"/>
    <mesh name="Little-PD" file="dphand/meshes_obj/PD.obj" scale="0.001 0.001 0.001"/>
    <mesh name="Little-PM" file="dphand/meshes_obj/PM.obj" scale="0.001 0.001 0.001"/>
    <mesh name="Little-PP" file="dphand/meshes_obj/PP.obj" scale="0.001 0.001 0.001"/>
    <mesh name="Little-MCP" file="dphand/meshes_obj/MCP.obj" scale="0.001 0.001 0.001"/>
    <mesh name="Index-MCP" file="dphand/meshes_obj/MCP.obj" scale="0.001 0.001 0.001"/>
    <mesh name="Forearm" file="dphand/meshes_obj/Forearm.obj" scale="0.001 0.001 0.001"/>
  </asset>

  <worldbody>
    <body name="link0" childclass="panda" quat="0.707105 0 0 0.707108">
      <inertial pos="0 0 0" quat="0.00630474 0.751245 0.00741774 0.659952" mass="0.629769" diaginertia="0.00430465 0.00387984 0.00313051"/>
      <geom class="panda/visual" material="off_white" mesh="link0_0"/>
      <geom class="panda/visual" material="dark_grey" mesh="link0_1"/>
      <geom class="panda/visual" material="off_white" mesh="link0_2"/>
      <geom class="panda/visual" material="dark_grey" mesh="link0_3"/>
      <geom class="panda/visual" material="off_white" mesh="link0_4"/>
      <geom class="panda/visual" material="dark_grey" mesh="link0_5"/>
      <geom class="panda/visual" material="white" mesh="link0_7"/>
      <geom class="panda/visual" material="white" mesh="link0_8"/>
      <geom class="panda/visual" material="dark_grey" mesh="link0_9"/>
      <geom class="panda/visual" material="off_white" mesh="link0_10"/>
      <geom class="panda/visual" material="white" mesh="link0_11"/>
      <geom class="panda/collision" mesh="link0_c"/>
      <body name="link1" pos="0 0 0.333">
        <inertial pos="0.003875 0.002081 -0.04762" quat="0.711549 0.00634377 -0.0131124 0.702485" mass="4.97068" diaginertia="0.707137 0.703435 0.00852456"/>
        <joint name="joint1" pos="0 0 0" axis="0 0 1"/>
        <geom class="panda/visual" material="white" mesh="link1"/>
        <geom class="panda/collision" mesh="link1_c"/>
        <site name="joint1" pos="0 0 0"/>
        <body name="link2" quat="0.707107 -0.707107 0 0">
          <inertial pos="-0.003141 -0.02872 0.003495" quat="-0.168175 0.828366 -0.122878 0.520027" mass="0.646926" diaginertia="0.0310326 0.0283001 0.00273425"/>
          <joint name="joint2" pos="0 0 0" axis="0 0 1" range="-1.7628 1.7628"/>
          <geom class="panda/visual" material="white" mesh="link2"/>
          <geom class="panda/collision" mesh="link2_c"/>
          <site name="joint2" pos="0 0 0"/>
          <body name="link3" pos="0 -0.316 0" quat="0.707107 0.707107 0 0">
            <inertial pos="0.027518 0.039252 -0.066502" quat="0.662769 -0.00678331 0.252053 0.705096" mass="3.2286" diaginertia="0.0415014 0.0414793 0.00124635"/>
            <joint name="joint3" pos="0 0 0" axis="0 0 1"/>
            <geom class="panda/visual" material="white" mesh="link3_0"/>
            <geom class="panda/visual" material="white" mesh="link3_1"/>
            <geom class="panda/visual" material="white" mesh="link3_2"/>
            <geom class="panda/visual" material="dark_grey" mesh="link3_3"/>
            <geom class="panda/collision" mesh="link3_c"/>
            <site name="joint3" pos="0 0 0"/>
            <body name="link4" pos="0.0825 0 0" quat="0.707107 0.707107 0 0">
              <inertial pos="-0.05317 0.104419 0.027454" quat="0.65058 0.529822 -0.0962034 0.535518" mass="3.5879" diaginertia="0.0349596 0.0281483 0.0106201"/>
              <joint name="joint4" pos="0 0 0" axis="0 0 1" range="-3.0718 -0.0698"/>
              <geom class="panda/visual" material="white" mesh="link4_0"/>
              <geom class="panda/visual" material="white" mesh="link4_1"/>
              <geom class="panda/visual" material="dark_grey" mesh="link4_2"/>
              <geom class="panda/visual" material="white" mesh="link4_3"/>
              <geom class="panda/collision" mesh="link4_c"/>
              <site name="joint4" pos="0 0 0"/>
              <body name="link5" pos="-0.0825 0.384 0" quat="0.707107 -0.707107 0 0">
                <inertial pos="-0.011953 0.041065 -0.038437" quat="0.987313 -0.0121954 0.0719187 -0.141037" mass="1.22595" diaginertia="0.0367625 0.0288531 0.00803437"/>
                <joint name="joint5" pos="0 0 0" axis="0 0 1"/>
                <geom class="panda/visual" material="dark_grey" mesh="link5_0"/>
                <geom class="panda/visual" material="white" mesh="link5_1"/>
                <geom class="panda/visual" material="white" mesh="link5_2"/>
                <geom class="panda/collision" mesh="link5_c0"/>
                <geom class="panda/collision" mesh="link5_c1"/>
                <geom class="panda/collision" mesh="link5_c2"/>
                <site name="joint5" pos="0 0 0"/>
                <body name="link6" quat="0.707107 0.707107 0 0">
                  <inertial pos="0.060149 -0.014117 -0.010517" quat="0.101075 0.59332 0.0287227 0.798079" mass="1.66656" diaginertia="0.00584276 0.00431037 0.00159787"/>
                  <joint name="joint6" pos="0 0 0" axis="0 0 1" range="-0.0175 3.7525"/>
                  <geom class="panda/visual" material="off_white" mesh="link6_0"/>
                  <geom class="panda/visual" material="white" mesh="link6_1"/>
                  <geom class="panda/visual" material="dark_grey" mesh="link6_2"/>
                  <geom class="panda/visual" material="white" mesh="link6_3"/>
                  <geom class="panda/visual" material="white" mesh="link6_4"/>
                  <geom class="panda/visual" material="white" mesh="link6_5"/>
                  <geom class="panda/visual" material="white" mesh="link6_6"/>
                  <geom class="panda/visual" material="light_blue" mesh="link6_7"/>
                  <geom class="panda/visual" material="light_blue" mesh="link6_8"/>
                  <geom class="panda/visual" material="dark_grey" mesh="link6_9"/>
                  <geom class="panda/visual" material="dark_grey" mesh="link6_10"/>
                  <geom class="panda/visual" material="white" mesh="link6_11"/>
                  <geom class="panda/visual" material="green" mesh="link6_12"/>
                  <geom class="panda/visual" material="white" mesh="link6_13"/>
                  <geom class="panda/visual" material="dark_grey" mesh="link6_14"/>
                  <geom class="panda/visual" material="dark_grey" mesh="link6_15"/>
                  <geom class="panda/visual" material="white" mesh="link6_16"/>
                  <geom class="panda/collision" mesh="link6_c"/>
                  <site name="joint6" pos="0 0 0"/>
                  <body name="link7" pos="0.088 0 0" quat="0.707107 0.707107 0 0">
                    <inertial pos="0.010517 -0.004252 0.061597" quat="0.992939 -0.0762041 0.0733595 -0.0537067" mass="0.735522" diaginertia="0.0127345 0.0101055 0.00451803"/>
                    <joint name="joint7" pos="0 0 0" axis="0 0 1"/>
                    <geom class="panda/visual" material="white" mesh="link7_0"/>
                    <geom class="panda/visual" material="dark_grey" mesh="link7_1"/>
                    <geom class="panda/visual" material="dark_grey" mesh="link7_2"/>
                    <geom class="panda/visual" material="dark_grey" mesh="link7_3"/>
                    <geom class="panda/visual" material="dark_grey" mesh="link7_4"/>
                    <geom class="panda/visual" material="dark_grey" mesh="link7_5"/>
                    <geom class="panda/visual" material="dark_grey" mesh="link7_6"/>
                    <geom class="panda/visual" material="white" mesh="link7_7"/>
                    <geom class="panda/collision" mesh="link7_c"/>
                    <site name="joint7" pos="0 0 0"/>
                    <body name="attachment" quat="0.382683 0 0 0.92388">
                      <geom size="0.01 0.01 0.01" type="box" rgba="1 0 0 0.5"/>
                      <site name="pinch" pos="0 0 0.147" quat="9.38184e-07 -0.707108 0.707105 -9.38187e-07"/>
                      <body name="Forearm" pos="0.107 0 0.147" quat="9.38184e-07 0.707105 -0.707108 9.38187e-07">
                        <inertial pos="-2.66154e-08 0.00901929 0.00320886" quat="0.502883 0.4971 -0.4971 0.502883" mass="1.94533" diaginertia="0.00960428 0.00906669 0.00209354"/>
                        <body name="Wrist" pos="0 0.13655 0" quat="0 0 -1 0">
                          <inertial pos="-1.69244e-07 0.00164725 -1.68006e-06" quat="0.501832 0.498155 0.49879 0.501213" mass="0.0265621" diaginertia="4.35913e-06 3.93694e-06 2.08125e-06"/>
                          <joint name="Forearm_Wrist-Flexion" class="jointconfig" pos="0.02 1.72024e-07 1.75115e-07" axis="1 0 0" range="-1.0472 1.0472" damping="2"/>
                          <geom size="0.04 0.04 0.03" pos="0 -0.03 -0.015" type="box" rgba="0.2 0.2 0.2 0.8"/>
                          <geom name="Wrist_geom" class="plastic" mesh="Wrist"/>
                          <camera name="wrist" pos="0 -0.05 0.06" quat="0.707105 0.707108 0 0" fovy="90"/>
                          <body name="Palm" pos="0.011291 0.0797134 0.0435865" quat="-2.82252e-06 0 1 0">
                            <inertial pos="0.00836675 -0.0219616 0.0507502" quat="0.468182 0.517884 -0.509503 0.502999" mass="0.260211" diaginertia="0.000208599 0.000168215 9.33263e-05"/>
                            <joint name="Wrist_Wrist-Abduction" class="jointconfig" pos="0.0112908 -0.0647132 0.0331363" axis="5.64503e-06 0 -1" range="-0.872665 0.523599" damping="0.1"/>
                            <geom name="Palm_geom" class="plastic" mesh="Palm"/>
                            <body name="Thumb-MCP" pos="0.0664645 -0.00613254 0.232169" quat="0.806444 0.162552 -0.473519 0.314651">
                              <inertial pos="-0.2 0.00771726 -0.0523825" quat="0.650782 0.276556 0.650782 0.276556" mass="0.00503699" diaginertia="1.74126e-07 1.44952e-07 1.29709e-07"/>
                              <joint name="Palm_Thumb-MCP-Flexion" class="jointconfig" pos="-0.191 0.00850011 -0.0532815" axis="1 -1.97734e-08 2.75775e-07" range="-0.523599 1.5708"/>
                              <geom name="Thumb-MCP_geom" class="plastic" mesh="Thumb-MCP"/>
                              <body name="Thumb-PP" pos="-0.19991 -8.97579e-05 -0.0918666" quat="0 0 0.707107 -0.707107">
                                <inertial pos="9.0303e-05 -0.0145312 -0.00588035" quat="0.633625 0.773641 0.000109551 -0.000126635" mass="0.0370886" diaginertia="5.75364e-06 5.59144e-06 2.26505e-06"/>
                                <joint name="Thumb-MCP_Thumb-MCP-Abduction" class="jointconfig" pos="9.00147e-05 -0.0368352 -0.0116207" axis="1.26824e-07 -0.5 0.866025" range="-0.610865 0.610865"/>
                                <geom name="Thumb-PP_geom" class="plastic" mesh="Thumb-PP"/>
                                <body name="Thumb-PM" pos="9.00863e-05 0.000633369 -8.9757e-05" quat="0 0 0.707107 -0.707107">
                                  <inertial pos="-1.84858e-07 0.00519583 -0.0187189" quat="0.70525 -0.0497224 0.0497361 0.705461" mass="0.0202272" diaginertia="2.02542e-06 1.99671e-06 7.90129e-07"/>
                                  <joint name="Thumb-PP_Thumb-PIP-Flexion" class="jointconfig" pos="0.00900005 0.00750001 -0.00749996" axis="1 -1.97734e-08 2.75775e-07" range="0 1.91986"/>
                                  <geom name="Thumb-PM_geom" class="plastic" mesh="Thumb-PM"/>
                                  <body name="Thumb-PD" pos="0 0.006 -0.030374" quat="1 0 0 0">
                                    <inertial pos="4.78256e-06 -0.00105952 -0.0142351" quat="0.705652 -0.0445682 0.045259 0.705706" mass="0.00822123" diaginertia="6.22404e-07 5.89825e-07 2.2354e-07"/>
                                    <joint name="Thumb-PM_Thumb-DIP-Flexion" class="jointconfig" pos="0.00750019 -1.01357e-08 -0.00599965" axis="1 -1.97734e-08 2.75775e-07" range="0 1.22173"/>
                                    <geom name="Thumb-PD_geom" class="plastic" mesh="Thumb-PD"/>
                                  </body>
                                </body>
                              </body>
                            </body>
                            <body name="Index-MCP" pos="-0.176119 0.0186063 0.0520866" quat="-0.092295 0.0922969 0.70105 -0.701065">
                              <inertial pos="-0.2 0.00771726 -0.0523825" quat="0.650782 0.276556 0.650782 0.276556" mass="0.00503699" diaginertia="1.74126e-07 1.44952e-07 1.29709e-07"/>
                              <joint name="Palm_Index-MCP-Flexion" class="jointconfig" pos="-0.191 0.00850018 -0.0532817" axis="1 1.93024e-12 8.85254e-08" range="-0.523599 1.5708"/>
                              <geom name="Index-MCP_geom" class="plastic" mesh="Index-MCP"/>
                              <body name="Index-PP" pos="-0.19991 -8.97579e-05 -0.0918666" quat="0 0 0.707107 -0.707107">
                                <inertial pos="9.0303e-05 -0.0145312 -0.00588035" quat="0.633625 0.773641 0.000109551 -0.000126635" mass="0.0370886" diaginertia="5.75364e-06 5.59144e-06 2.26505e-06"/>
                                <joint name="Index-MCP_Index-MCP-Abduction" class="jointconfig" pos="8.99993e-05 -0.036835 -0.0116209" axis="-2.67814e-07 -0.500001 0.866025" range="-0.610865 0.610865"/>
                                <geom name="Index-PP_geom" class="plastic" mesh="Index-PP"/>
                                <body name="Index-PM" pos="9.00863e-05 0.000633369 -8.9757e-05" quat="0 0 0.707107 -0.707107">
                                  <inertial pos="-1.84858e-07 0.00519583 -0.0187189" quat="0.70525 -0.0497224 0.0497361 0.705461" mass="0.0202272" diaginertia="2.02542e-06 1.99671e-06 7.90129e-07"/>
                                  <joint name="Index-PP_Index-PIP-Flexion" class="jointconfig" pos="0.00900029 0.00750016 -0.00749941" axis="1 1.94022e-12 8.85254e-08" range="0 1.91986"/>
                                  <geom name="Index-PM_geom" class="plastic" mesh="Index-PM"/>
                                  <body name="Index-PD" pos="0 0.006 -0.030374" quat="1 0 0 0">
                                    <inertial pos="4.78256e-06 -0.00105952 -0.0142351" quat="0.705652 -0.0445682 0.045259 0.705706" mass="0.00822123" diaginertia="6.22404e-07 5.89825e-07 2.2354e-07"/>
                                    <joint name="Index-PM_Index-DIP-Flexion" class="jointconfig" pos="0.00750034 -4.76857e-07 -0.00599944" axis="1 1.94016e-12 8.85254e-08" range="0 1.22173"/>
                                    <geom name="Index-PD_geom" class="plastic" mesh="Index-PD"/>
                                  </body>
                                </body>
                              </body>
                            </body>
                            <body name="Middle-MCP" pos="-0.188709 -0.0297305 0.0520854" quat="1.99582e-06 1.99582e-06 0.707107 -0.707107">
                              <inertial pos="-0.2 0.00771726 -0.0523825" quat="0.650782 0.276556 0.650782 0.276556" mass="0.00503699" diaginertia="1.74126e-07 1.44952e-07 1.29709e-07"/>
                              <joint name="Palm_Middle-MCP-Flexion" class="jointconfig" pos="-0.191 0.00850018 -0.0532823" axis="1 0 0" range="-0.523599 1.5708"/>
                              <geom name="Middle-MCP_geom" class="plastic" mesh="Middle-MCP"/>
                              <body name="Middle-PP" pos="-0.19991 -8.97579e-05 -0.0918666" quat="0 0 -0.707107 0.707107">
                                <inertial pos="9.0303e-05 -0.0145312 -0.00588035" quat="0.633625 0.773641 0.000109551 -0.000126635" mass="0.0370886" diaginertia="5.75364e-06 5.59144e-06 2.26505e-06"/>
                                <joint name="Middle-MCP_Middle-MCP-Abduction" class="jointconfig" pos="9.00624e-05 -0.0368344 -0.0116209" axis="0 -0.5 0.866025" range="-0.610865 0.610865"/>
                                <geom name="Middle-PP_geom" class="plastic" mesh="Middle-PP"/>
                                <body name="Middle-PM" pos="9.00863e-05 0.000633369 -8.9757e-05" quat="0 0 -0.707107 0.707107">
                                  <inertial pos="-1.84858e-07 0.00519583 -0.0187189" quat="0.70525 -0.0497224 0.0497361 0.705461" mass="0.0202272" diaginertia="2.02542e-06 1.99671e-06 7.90129e-07"/>
                                  <joint name="Middle-PP_Middle-PIP-Flexion" class="jointconfig" pos="0.00900002 0.00750018 -0.00750027" axis="1 0 0" range="0 1.91986"/>
                                  <geom name="Middle-PM_geom" class="plastic" mesh="Middle-PM"/>
                                  <body name="Middle-PD" pos="0 0.006 -0.030374" quat="1 0 0 0">
                                    <inertial pos="4.78256e-06 -0.00105952 -0.0142351" quat="0.705652 -0.0445682 0.045259 0.705706" mass="0.00822123" diaginertia="6.22404e-07 5.89825e-07 2.2354e-07"/>
                                    <joint name="Middle-PM_Middle-DIP-Flexion" class="jointconfig" pos="0.00750002 1.71977e-07 -0.00600026" axis="1 0 0" range="0 1.22173"/>
                                    <geom name="Middle-PD_geom" class="plastic" mesh="Middle-PD"/>
                                  </body>
                                </body>
                              </body>
                            </body>
                            <body name="Ring-MCP" pos="-0.18767 -0.0849217 0.0520842" quat="0.0922969 -0.092295 0.701065 -0.70105">
                              <inertial pos="-0.2 0.00771726 -0.0523825" quat="0.650782 0.276556 0.650782 0.276556" mass="0.00503699" diaginertia="1.74126e-07 1.44952e-07 1.29709e-07"/>
                              <joint name="Palm_Ring-MCP-Flexion" class="jointconfig" pos="-0.191 0.00850018 -0.0532813" axis="1 1.93041e-12 -8.85254e-08" range="-0.523599 1.5708"/>
                              <geom name="Ring-MCP_geom" class="plastic" mesh="Ring-MCP"/>
                              <body name="Ring-PP" pos="-0.19991 -8.97579e-05 -0.0918666" quat="0 0 -0.707107 0.707107">
                                <inertial pos="9.0303e-05 -0.0145312 -0.00588035" quat="0.633625 0.773641 0.000109551 -0.000126635" mass="0.0370886" diaginertia="5.75364e-06 5.59144e-06 2.26505e-06"/>
                                <joint name="Ring-MCP_Ring-MCP-Abduction" class="jointconfig" pos="9.01272e-05 -0.0368351 -0.011621" axis="-3.56339e-07 -0.5 0.866025" range="-0.610865 0.610865"/>
                                <geom name="Ring-PP_geom" class="plastic" mesh="Ring-PP"/>
                                <body name="Ring-PM" pos="9.00863e-05 0.000633369 -8.9757e-05" quat="0 0 -0.707107 0.707107">
                                  <inertial pos="-1.84858e-07 0.00519583 -0.0187189" quat="0.70525 -0.0497224 0.0497361 0.705461" mass="0.0202272" diaginertia="2.02542e-06 1.99671e-06 7.90129e-07"/>
                                  <joint name="Ring-PP_Ring-PIP-Flexion" class="jointconfig" pos="0.00899989 0.00750019 -0.00750027" axis="1 1.92196e-12 -8.85254e-08" range="0 1.91986"/>
                                  <geom name="Ring-PM_geom" class="plastic" mesh="Ring-PM"/>
                                  <body name="Ring-PD" pos="0 0.006 -0.030374" quat="1 0 0 0">
                                    <inertial pos="4.78256e-06 -0.00105952 -0.0142351" quat="0.705652 -0.0445682 0.045259 0.705706" mass="0.00822123" diaginertia="6.22404e-07 5.89825e-07 2.2354e-07"/>
                                    <joint name="Ring-PM_Ring-DIP-Flexion" class="jointconfig" pos="0.00749974 -1.79431e-07 -0.00599987" axis="1 1.92208e-12 -8.85254e-08" range="0 1.22173"/>
                                    <geom name="Ring-PD_geom" class="plastic" mesh="Ring-PD"/>
                                  </body>
                                </body>
                              </body>
                            </body>
                            <body name="Little-MCP" pos="-0.158751 -0.160558 0.052085" quat="-0.212632 0.21263 -0.674382 0.674377">
                              <inertial pos="-0.2 0.00771726 -0.0523825" quat="0.650782 0.276556 0.650782 0.276556" mass="0.00503699" diaginertia="1.74126e-07 1.44952e-07 1.29709e-07"/>
                              <joint name="Palm_Little-MCP-Flexion" class="jointconfig" pos="-0.191 0.00850018 -0.0532819" axis="1 3.26784e-12 -3.32035e-07" range="-0.523599 1.5708"/>
                              <geom name="Little-MCP_geom" class="plastic" mesh="Little-MCP"/>
                              <body name="Little-PP" pos="-0.19991 -8.97579e-05 -0.0918666" quat="0 0 -0.707107 0.707107">
                                <inertial pos="9.0303e-05 -0.0145312 -0.00588035" quat="0.633625 0.773641 0.000109551 -0.000126635" mass="0.0370886" diaginertia="5.75364e-06 5.59144e-06 2.26505e-06"/>
                                <joint name="Little-MCP_Little-MCP-Abduction" class="jointconfig" pos="9.03265e-05 -0.0368347 -0.011621" axis="-8.52922e-08 -0.5 0.866025" range="-0.610865 0.610865"/>
                                <geom name="Little-PP_geom" class="plastic" mesh="Little-PP"/>
                                <body name="Little-PM" pos="9.00863e-05 0.000633369 -8.9757e-05" quat="0 0 -0.707107 0.707107">
                                  <inertial pos="-1.84858e-07 0.00519583 -0.0187189" quat="0.70525 -0.0497224 0.0497361 0.705461" mass="0.0202272" diaginertia="2.02542e-06 1.99671e-06 7.90129e-07"/>
                                  <joint name="Little-PP_Little-PIP-Flexion" class="jointconfig" pos="0.00900005 0.00749963 -0.00749963" axis="1 3.23206e-12 -3.32035e-07" range="0 1.91986"/>
                                  <geom name="Little-PM_geom" class="plastic" mesh="Little-PM"/>
                                  <body name="Little-PD" pos="0 0.006 -0.030374" quat="1 0 0 0">
                                    <inertial pos="4.78256e-06 -0.00105952 -0.0142351" quat="0.705652 -0.0445682 0.045259 0.705706" mass="0.00822123" diaginertia="6.22404e-07 5.89825e-07 2.2354e-07"/>
                                    <joint name="Little-PM_Little-DIP-Flexion" class="jointconfig" pos="0.00750003 -8.41823e-08 -0.00600015" axis="1 3.23144e-12 -3.32035e-07" range="0 1.22173"/>
                                    <geom name="Little-PD_geom" class="plastic" mesh="Little-PD"/>
                                  </body>
                                </body>
                              </body>
                            </body>
                          </body>
                        </body>
                      </body>
                    </body>
                  </body>
                </body>
              </body>
            </body>
          </body>
        </body>
      </body>
    </body>
  </worldbody>

  <contact>
    <exclude name="Wrist_Forearm-exclude" body1="Forearm" body2="Wrist"/>
    <exclude name="Palm_Forearm-exclude" body1="Forearm" body2="Palm"/>
    <exclude name="Thumb-PP-exclude" body1="Palm" body2="Thumb-PP"/>
    <exclude name="Index-PP-exclude" body1="Palm" body2="Index-PP"/>
    <exclude name="Middle-PP-exclude" body1="Palm" body2="Middle-PP"/>
    <exclude name="Ring-PP-exclude" body1="Palm" body2="Ring-PP"/>
    <exclude name="Little-PP-exclude" body1="Palm" body2="Little-PP"/>
  </contact>

  <actuator>
    <general name="actuator1" class="panda" joint="joint1" ctrlrange="-87 87"/>
    <general name="actuator2" class="panda" joint="joint2" ctrlrange="-87 87"/>
    <general name="actuator3" class="panda" joint="joint3" ctrlrange="-87 87"/>
    <general name="actuator4" class="panda" joint="joint4" ctrlrange="-87 87"/>
    <general name="actuator5" class="panda" joint="joint5" ctrlrange="-12 12"/>
    <general name="actuator6" class="panda" joint="joint6" ctrlrange="-12 12"/>
    <general name="actuator7" class="panda" joint="joint7" ctrlrange="-12 12"/>
    <general name="Wrist" joint="Forearm_Wrist-Flexion" ctrlrange="-1.0472 1.0472" forcerange="-500 500" biastype="affine" gainprm="50" biasprm="0 -50"/>
    <general name="Palm" joint="Wrist_Wrist-Abduction" ctrlrange="-0.523599 0.523599" forcerange="-500 500" biastype="affine" gainprm="50" biasprm="0 -50"/>
    <general name="Thumb-MCP" class="MCPCtrl" joint="Palm_Thumb-MCP-Flexion" biasprm="0 -0.2 -0.0151927"/>
    <general name="Thumb-PP" class="MCP2Ctrl" joint="Thumb-MCP_Thumb-MCP-Abduction" biasprm="0 -0.2 -0.0145284"/>
    <general name="Thumb-PM" class="PIPCtrl" joint="Thumb-PP_Thumb-PIP-Flexion" biasprm="0 -0.2 -0.0118476"/>
    <general name="Thumb-PD" class="DIPCtrl" joint="Thumb-PM_Thumb-DIP-Flexion" biasprm="0 -0.2 -0.0114171"/>
    <general name="Index-MCP" class="MCPCtrl" joint="Palm_Index-MCP-Flexion" biasprm="0 -0.2 -0.0151927"/>
    <general name="Index-PP" class="MCP2Ctrl" joint="Index-MCP_Index-MCP-Abduction" biasprm="0 -0.2 -0.0145284"/>
    <general name="Index-PM" class="PIPCtrl" joint="Index-PP_Index-PIP-Flexion" biasprm="0 -0.2 -0.0118477"/>
    <general name="Index-PD" class="DIPCtrl" joint="Index-PM_Index-DIP-Flexion" biasprm="0 -0.2 -0.0114171"/>
    <general name="Middle-MCP" class="MCPCtrl" joint="Palm_Middle-MCP-Flexion" biasprm="0 -0.2 -0.0151926"/>
    <general name="Middle-PP" class="MCP2Ctrl" joint="Middle-MCP_Middle-MCP-Abduction" biasprm="0 -0.2 -0.0145284"/>
    <general name="Middle-PM" class="PIPCtrl" joint="Middle-PP_Middle-PIP-Flexion" biasprm="0 -0.2 -0.0118476"/>
    <general name="Middle-PD" class="DIPCtrl" joint="Middle-PM_Middle-DIP-Flexion" biasprm="0 -0.2 -0.0114171"/>
    <general name="Ring-MCP" class="MCPCtrl" joint="Palm_Ring-MCP-Flexion" biasprm="0 -0.2 -0.0151928"/>
    <general name="Ring-PP" class="MCP2Ctrl" joint="Ring-MCP_Ring-MCP-Abduction" biasprm="0 -0.2 -0.0145284"/>
    <general name="Ring-PM" class="PIPCtrl" joint="Ring-PP_Ring-PIP-Flexion" biasprm="0 -0.2 -0.0118476"/>
    <general name="Ring-PD" class="DIPCtrl" joint="Ring-PM_Ring-DIP-Flexion" biasprm="0 -0.2 -0.0114171"/>
    <general name="Little-MCP" class="MCPCtrl" joint="Palm_Little-MCP-Flexion" biasprm="0 -0.2 -0.0151927"/>
    <general name="Little-PP" class="MCP2Ctrl" joint="Little-MCP_Little-MCP-Abduction" biasprm="0 -0.2 -0.0145284"/>
    <general name="Little-PM" class="PIPCtrl" joint="Little-PP_Little-PIP-Flexion" biasprm="0 -0.2 -0.0118476"/>
    <general name="Little-PD" class="DIPCtrl" joint="Little-PM_Little-DIP-Flexion" biasprm="0 -0.2 -0.0114171"/>
  </actuator>

  <sensor>
    <framepos objtype="site" objname="pinch" name="tcp_pos"/>
    <framequat objtype="site" objname="pinch" name="tcp_quat"/>
    <framelinvel objtype="site" objname="pinch" name="tcp_linvel"/>
    <frameangvel objtype="site" objname="pinch" name="tcp_angvel"/>
  </sensor>
</mujoco>
